multiprocessing.pool.RemoteTraceback: 
"""
Traceback (most recent call last):
  File "/Users/chenling/Desktop/DSBOX/P4ML-UI/dsbox-ta2/python/dsbox/executer/executionhelper.py", line 358, in cross_validation_score
    executable.fit(trainX, trainY)
  File "/anaconda3/lib/python3.6/site-packages/sklearn/linear_model/stochastic_gradient.py", line 586, in fit
    sample_weight=sample_weight)
  File "/anaconda3/lib/python3.6/site-packages/sklearn/linear_model/stochastic_gradient.py", line 414, in _fit
    self._validate_params()
  File "/anaconda3/lib/python3.6/site-packages/sklearn/linear_model/stochastic_gradient.py", line 128, in _validate_params
    "and default tol will be 1e-3." % type(self), FutureWarning)
  File "/anaconda3/lib/python3.6/warnings.py", line 101, in _showwarnmsg
    _showwarnmsg_impl(msg)
  File "/anaconda3/lib/python3.6/warnings.py", line 30, in _showwarnmsg_impl
    file.write(text)
TypeError: a bytes-like object is required, not 'str'

During handling of the above exception, another exception occurred:

Traceback (most recent call last):
  File "/anaconda3/lib/python3.6/multiprocessing/pool.py", line 119, in worker
    result = (True, func(*args, **kwds))
  File "/anaconda3/lib/python3.6/site-packages/stopit/utils.py", line 148, in wrapper
    return func(*args, **kwargs)
  File "/Users/chenling/Desktop/DSBOX/P4ML-UI/dsbox-ta2/python/dsbox/executer/executionhelper.py", line 372, in cross_validation_score
    traceback.print_exc(e)
  File "/anaconda3/lib/python3.6/traceback.py", line 163, in print_exc
    print_exception(*sys.exc_info(), limit=limit, file=file, chain=chain)
  File "/anaconda3/lib/python3.6/traceback.py", line 104, in print_exception
    type(value), value, tb, limit=limit).format(chain=chain):
  File "/anaconda3/lib/python3.6/traceback.py", line 509, in __init__
    capture_locals=capture_locals)
  File "/anaconda3/lib/python3.6/traceback.py", line 338, in extract
    if limit >= 0:
TypeError: '>=' not supported between instances of 'TypeError' and 'int'
"""

The above exception was the direct cause of the following exception:

Traceback (most recent call last):
  File "/Users/chenling/Desktop/DSBOX/P4ML-UI/dsbox-ta2/python/dsbox/planner/common/resource_manager.py", line 39, in execute_pipelines
    retvalue = exref.get(timeout=TIMEOUT)
  File "/anaconda3/lib/python3.6/multiprocessing/pool.py", line 644, in get
    raise self._value
TypeError: '>=' not supported between instances of 'TypeError' and 'int'
ERROR execute_pipelines([Label Encoder, Imputer, ExtraTreeClassifier]) : '>=' not supported between instances of 'TypeError' and 'int'
multiprocessing.pool.RemoteTraceback: 
"""
Traceback (most recent call last):
  File "/Users/chenling/Desktop/DSBOX/P4ML-UI/dsbox-ta2/python/dsbox/executer/executionhelper.py", line 358, in cross_validation_score
    executable.fit(trainX, trainY)
  File "/anaconda3/lib/python3.6/site-packages/sklearn/linear_model/passive_aggressive.py", line 225, in fit
    coef_init=coef_init, intercept_init=intercept_init)
  File "/anaconda3/lib/python3.6/site-packages/sklearn/linear_model/stochastic_gradient.py", line 414, in _fit
    self._validate_params()
  File "/anaconda3/lib/python3.6/site-packages/sklearn/linear_model/stochastic_gradient.py", line 128, in _validate_params
    "and default tol will be 1e-3." % type(self), FutureWarning)
  File "/anaconda3/lib/python3.6/warnings.py", line 101, in _showwarnmsg
    _showwarnmsg_impl(msg)
  File "/anaconda3/lib/python3.6/warnings.py", line 30, in _showwarnmsg_impl
    file.write(text)
TypeError: a bytes-like object is required, not 'str'

During handling of the above exception, another exception occurred:

Traceback (most recent call last):
  File "/anaconda3/lib/python3.6/multiprocessing/pool.py", line 119, in worker
    result = (True, func(*args, **kwds))
  File "/anaconda3/lib/python3.6/site-packages/stopit/utils.py", line 148, in wrapper
    return func(*args, **kwargs)
  File "/Users/chenling/Desktop/DSBOX/P4ML-UI/dsbox-ta2/python/dsbox/executer/executionhelper.py", line 372, in cross_validation_score
    traceback.print_exc(e)
  File "/anaconda3/lib/python3.6/traceback.py", line 163, in print_exc
    print_exception(*sys.exc_info(), limit=limit, file=file, chain=chain)
  File "/anaconda3/lib/python3.6/traceback.py", line 104, in print_exception
    type(value), value, tb, limit=limit).format(chain=chain):
  File "/anaconda3/lib/python3.6/traceback.py", line 509, in __init__
    capture_locals=capture_locals)
  File "/anaconda3/lib/python3.6/traceback.py", line 338, in extract
    if limit >= 0:
TypeError: '>=' not supported between instances of 'TypeError' and 'int'
"""

The above exception was the direct cause of the following exception:

Traceback (most recent call last):
  File "/Users/chenling/Desktop/DSBOX/P4ML-UI/dsbox-ta2/python/dsbox/planner/common/resource_manager.py", line 39, in execute_pipelines
    retvalue = exref.get(timeout=TIMEOUT)
  File "/anaconda3/lib/python3.6/multiprocessing/pool.py", line 644, in get
    raise self._value
TypeError: '>=' not supported between instances of 'TypeError' and 'int'
ERROR execute_pipelines([Label Encoder, Imputer, ExtraTreeClassifier]) : '>=' not supported between instances of 'TypeError' and 'int'
multiprocessing.pool.RemoteTraceback: 
"""
Traceback (most recent call last):
  File "/Users/chenling/Desktop/DSBOX/P4ML-UI/dsbox-ta2/python/dsbox/executer/executionhelper.py", line 358, in cross_validation_score
    executable.fit(trainX, trainY)
  File "/anaconda3/lib/python3.6/site-packages/sklearn/linear_model/stochastic_gradient.py", line 586, in fit
    sample_weight=sample_weight)
  File "/anaconda3/lib/python3.6/site-packages/sklearn/linear_model/stochastic_gradient.py", line 414, in _fit
    self._validate_params()
  File "/anaconda3/lib/python3.6/site-packages/sklearn/linear_model/stochastic_gradient.py", line 128, in _validate_params
    "and default tol will be 1e-3." % type(self), FutureWarning)
  File "/anaconda3/lib/python3.6/warnings.py", line 101, in _showwarnmsg
    _showwarnmsg_impl(msg)
  File "/anaconda3/lib/python3.6/warnings.py", line 30, in _showwarnmsg_impl
    file.write(text)
TypeError: a bytes-like object is required, not 'str'

During handling of the above exception, another exception occurred:

Traceback (most recent call last):
  File "/anaconda3/lib/python3.6/multiprocessing/pool.py", line 119, in worker
    result = (True, func(*args, **kwds))
  File "/anaconda3/lib/python3.6/site-packages/stopit/utils.py", line 148, in wrapper
    return func(*args, **kwargs)
  File "/Users/chenling/Desktop/DSBOX/P4ML-UI/dsbox-ta2/python/dsbox/executer/executionhelper.py", line 372, in cross_validation_score
    traceback.print_exc(e)
  File "/anaconda3/lib/python3.6/traceback.py", line 163, in print_exc
    print_exception(*sys.exc_info(), limit=limit, file=file, chain=chain)
  File "/anaconda3/lib/python3.6/traceback.py", line 104, in print_exception
    type(value), value, tb, limit=limit).format(chain=chain):
  File "/anaconda3/lib/python3.6/traceback.py", line 509, in __init__
    capture_locals=capture_locals)
  File "/anaconda3/lib/python3.6/traceback.py", line 338, in extract
    if limit >= 0:
TypeError: '>=' not supported between instances of 'TypeError' and 'int'
"""

The above exception was the direct cause of the following exception:

Traceback (most recent call last):
  File "/Users/chenling/Desktop/DSBOX/P4ML-UI/dsbox-ta2/python/dsbox/planner/common/resource_manager.py", line 39, in execute_pipelines
    retvalue = exref.get(timeout=TIMEOUT)
  File "/anaconda3/lib/python3.6/multiprocessing/pool.py", line 644, in get
    raise self._value
TypeError: '>=' not supported between instances of 'TypeError' and 'int'
ERROR execute_pipelines([Label Encoder, Imputer, ExtraTreeClassifier]) : '>=' not supported between instances of 'TypeError' and 'int'
